<?xml version="1.0"?>
<robot xmlns:xacro="http://www.ros.org/wiki/xacro" name="scout_mini">

  <!-- ============================================================== -->
  <!-- Properties: Scout Mini physical parameters                     -->
  <!-- Source: AgileX official specifications                          -->
  <!-- ============================================================== -->
  <xacro:property name="base_length" value="0.612"/>
  <xacro:property name="base_width"  value="0.580"/>
  <xacro:property name="base_height" value="0.245"/>
  <xacro:property name="base_mass"   value="22.0"/>

  <xacro:property name="wheel_radius"    value="0.090"/>
  <xacro:property name="wheel_width"     value="0.060"/>
  <xacro:property name="wheel_mass"      value="1.5"/>
  <xacro:property name="wheelbase"       value="0.452"/>
  <xacro:property name="track_width"     value="0.490"/>

  <!-- Wheel vertical offset: bottom of base sits above ground by wheel_radius -->
  <xacro:property name="base_z_offset" value="${wheel_radius}"/>

  <!-- ============================================================== -->
  <!-- Inertial macros                                                 -->
  <!-- ============================================================== -->
  <xacro:macro name="box_inertia" params="m x y z">
    <inertial>
      <mass value="${m}"/>
      <inertia
        ixx="${m*(y*y + z*z)/12.0}" ixy="0.0" ixz="0.0"
        iyy="${m*(x*x + z*z)/12.0}" iyz="0.0"
        izz="${m*(x*x + y*y)/12.0}"/>
    </inertial>
  </xacro:macro>

  <xacro:macro name="cylinder_inertia" params="m r h">
    <inertial>
      <mass value="${m}"/>
      <inertia
        ixx="${m*(3*r*r + h*h)/12.0}" ixy="0.0" ixz="0.0"
        iyy="${m*(3*r*r + h*h)/12.0}" iyz="0.0"
        izz="${m*r*r/2.0}"/>
    </inertial>
  </xacro:macro>

  <!-- ============================================================== -->
  <!-- base_footprint: virtual frame on the ground                    -->
  <!-- ============================================================== -->
  <link name="base_footprint"/>

  <!-- ============================================================== -->
  <!-- base_link: main body                                            -->
  <!-- ============================================================== -->
  <link name="base_link">
    <visual>
      <origin xyz="0 0 ${base_height/2}" rpy="0 0 0"/>
      <geometry>
        <box size="${base_length} ${base_width} ${base_height}"/>
      </geometry>
      <material name="scout_yellow">
        <color rgba="0.95 0.75 0.05 1.0"/>
      </material>
    </visual>
    <collision>
      <origin xyz="0 0 ${base_height/2}" rpy="0 0 0"/>
      <geometry>
        <box size="${base_length} ${base_width} ${base_height}"/>
      </geometry>
    </collision>
    <xacro:box_inertia m="${base_mass}" x="${base_length}" y="${base_width}" z="${base_height}"/>
  </link>

  <joint name="base_footprint_to_base_link" type="fixed">
    <parent link="base_footprint"/>
    <child link="base_link"/>
    <origin xyz="0 0 ${base_z_offset}" rpy="0 0 0"/>
  </joint>

  <!-- ============================================================== -->
  <!-- Wheel macro                                                     -->
  <!-- Reused for all four wheels                                      -->
  <!-- ============================================================== -->
  <xacro:macro name="wheel" params="prefix x_offset y_offset">
    <link name="${prefix}_wheel_link">
      <visual>
        <origin xyz="0 0 0" rpy="${pi/2} 0 0"/>
        <geometry>
          <cylinder radius="${wheel_radius}" length="${wheel_width}"/>
        </geometry>
        <material name="wheel_black">
          <color rgba="0.1 0.1 0.1 1.0"/>
        </material>
      </visual>
      <collision>
        <origin xyz="0 0 0" rpy="${pi/2} 0 0"/>
        <geometry>
          <cylinder radius="${wheel_radius}" length="${wheel_width}"/>
        </geometry>
      </collision>
      <xacro:cylinder_inertia m="${wheel_mass}" r="${wheel_radius}" h="${wheel_width}"/>
    </link>

    <joint name="${prefix}_wheel_joint" type="continuous">
      <parent link="base_link"/>
      <child link="${prefix}_wheel_link"/>
      <origin xyz="${x_offset} ${y_offset} 0" rpy="0 0 0"/>
      <axis xyz="0 1 0"/>
    </joint>
  </xacro:macro>

  <!-- Instantiate four wheels -->
  <xacro:wheel prefix="front_left"  x_offset="${ wheelbase/2}" y_offset="${ track_width/2}"/>
  <xacro:wheel prefix="front_right" x_offset="${ wheelbase/2}" y_offset="${-track_width/2}"/>
  <xacro:wheel prefix="rear_left"   x_offset="${-wheelbase/2}" y_offset="${ track_width/2}"/>
  <xacro:wheel prefix="rear_right"  x_offset="${-wheelbase/2}" y_offset="${-track_width/2}"/>

  <!-- IMU sensor                                                      -->
  <!-- Mounted on the top center of base_link                          -->
  <link name="imu_link">
    <visual>
      <geometry>
        <box size="0.04 0.04 0.02"/>
      </geometry>
      <material name="imu_blue">
        <color rgba="0.0 0.3 0.8 1.0"/>
      </material>
    </visual>
    <collision>
      <geometry>
        <box size="0.04 0.04 0.02"/>
      </geometry>
    </collision>
    <inertial>
      <mass value="0.05"/>
      <inertia
        ixx="1e-5" ixy="0.0" ixz="0.0"
        iyy="1e-5" iyz="0.0"
        izz="1e-5"/>
    </inertial>
  </link>

  <joint name="imu_joint" type="fixed">
    <parent link="base_link"/>
    <child link="imu_link"/>
    <origin xyz="0 0 ${base_height + 0.01}" rpy="0 0 0"/>
  </joint>

  <!-- 2D Lidar (LSLIDAR N10-class)                                    -->
  <!-- Mounted on the top of base_link, forward of IMU                 -->
  <link name="lidar_link">
    <visual>
      <geometry>
        <cylinder radius="0.04" length="0.06"/>
      </geometry>
      <material name="lidar_dark">
        <color rgba="0.2 0.2 0.2 1.0"/>
      </material>
    </visual>
    <collision>
      <geometry>
        <cylinder radius="0.04" length="0.06"/>
      </geometry>
    </collision>
    <inertial>
      <mass value="0.2"/>
      <inertia
        ixx="2e-4" ixy="0.0" ixz="0.0"
        iyy="2e-4" iyz="0.0"
        izz="1e-4"/>
    </inertial>
  </link>

  <joint name="lidar_joint" type="fixed">
    <parent link="base_link"/>
    <child link="lidar_link"/>
    <origin xyz="0.20 0 ${base_height + 0.03}" rpy="0 0 0"/>
  </joint>

  <xacro:include filename="$(find scout_mini_description)/urdf/scout_mini.gazebo.xacro"/>

</robot>